2025-06-05 05:44:12 | ERROR    | stealth_bot:224 | Failed to create Chrome driver: [Errno 2] No such file or directory: '/home/runner/.local/share/undetected_chromedriver/undetected/chromedriver-linux64/chromedriver' -> '/home/runner/.local/share/undetected_chromedriver/undetected_chromedriver'
2025-06-05 05:44:12 | ERROR    | stealth_bot:466 | Fatal error during bot execution: [Errno 2] No such file or directory: '/home/runner/.local/share/undetected_chromedriver/undetected/chromedriver-linux64/chromedriver' -> '/home/runner/.local/share/undetected_chromedriver/undetected_chromedriver'
Traceback (most recent call last):
  File "/home/runner/workspace/bot/stealth_bot.py", line 446, in run
    self.driver = self._create_driver()
                  ^^^^^^^^^^^^^^^^^^^^^
  File "/home/runner/workspace/bot/stealth_bot.py", line 204, in _create_driver
    driver = uc.Chrome(
             ^^^^^^^^^^
  File "/home/runner/workspace/.pythonlibs/lib/python3.11/site-packages/undetected_chromedriver/__init__.py", line 258, in __init__
    self.patcher.auto()
  File "/home/runner/workspace/.pythonlibs/lib/python3.11/site-packages/undetected_chromedriver/patcher.py", line 178, in auto
    self.unzip_package(self.fetch_package())
  File "/home/runner/workspace/.pythonlibs/lib/python3.11/site-packages/undetected_chromedriver/patcher.py", line 310, in unzip_package
    os.rename(os.path.join(self.zip_path, exe_path), self.executable_path)
FileNotFoundError: [Errno 2] No such file or directory: '/home/runner/.local/share/undetected_chromedriver/undetected/chromedriver-linux64/chromedriver' -> '/home/runner/.local/share/undetected_chromedriver/undetected_chromedriver'
2025-06-05 05:44:12 | ERROR    | stealth_bot:224 | Failed to create Chrome driver: Binary Location Must be a String
2025-06-05 05:44:12 | ERROR    | stealth_bot:466 | Fatal error during bot execution: Binary Location Must be a String
Traceback (most recent call last):
  File "/home/runner/workspace/bot/stealth_bot.py", line 446, in run
    self.driver = self._create_driver()
                  ^^^^^^^^^^^^^^^^^^^^^
  File "/home/runner/workspace/bot/stealth_bot.py", line 204, in _create_driver
    driver = uc.Chrome(
             ^^^^^^^^^^
  File "/home/runner/workspace/.pythonlibs/lib/python3.11/site-packages/undetected_chromedriver/__init__.py", line 372, in __init__
    options.binary_location = (
    ^^^^^^^^^^^^^^^^^^^^^^^
  File "/home/runner/workspace/.pythonlibs/lib/python3.11/site-packages/selenium/webdriver/chromium/options.py", line 50, in binary_location
    raise TypeError(self.BINARY_LOCATION_ERROR)
TypeError: Binary Location Must be a String
2025-06-05 05:46:40 | ERROR    | stealth_bot:271 | Failed to create Chrome driver: Message: Service /home/runner/.cache/selenium/chromedriver/linux64/125.0.6422.141/chromedriver unexpectedly exited. Status code was: 127

2025-06-05 05:46:40 | ERROR    | stealth_bot:271 | Failed to create Chrome driver: Message: Service /home/runner/.cache/selenium/chromedriver/linux64/125.0.6422.141/chromedriver unexpectedly exited. Status code was: 127

2025-06-05 05:46:40 | ERROR    | stealth_bot:286 | All driver creation attempts failed: Message: Service /home/runner/.cache/selenium/chromedriver/linux64/125.0.6422.141/chromedriver unexpectedly exited. Status code was: 127

2025-06-05 05:46:40 | ERROR    | stealth_bot:286 | All driver creation attempts failed: Message: Service /home/runner/.cache/selenium/chromedriver/linux64/125.0.6422.141/chromedriver unexpectedly exited. Status code was: 127

2025-06-05 05:46:40 | ERROR    | stealth_bot:539 | Fatal error during bot execution: Cannot create Chrome driver. Original error: Message: Service /home/runner/.cache/selenium/chromedriver/linux64/125.0.6422.141/chromedriver unexpectedly exited. Status code was: 127
, Final error: Message: Service /home/runner/.cache/selenium/chromedriver/linux64/125.0.6422.141/chromedriver unexpectedly exited. Status code was: 127
Traceback (most recent call last):
  File "/home/runner/workspace/bot/stealth_bot.py", line 242, in _create_driver
    driver = uc.Chrome(
             ^^^^^^^^^^
  File "/home/runner/workspace/.pythonlibs/lib/python3.11/site-packages/undetected_chromedriver/__init__.py", line 258, in __init__
    self.patcher.auto()
  File "/home/runner/workspace/.pythonlibs/lib/python3.11/site-packages/undetected_chromedriver/patcher.py", line 178, in auto
    self.unzip_package(self.fetch_package())
  File "/home/runner/workspace/.pythonlibs/lib/python3.11/site-packages/undetected_chromedriver/patcher.py", line 310, in unzip_package
    os.rename(os.path.join(self.zip_path, exe_path), self.executable_path)
FileNotFoundError: [Errno 2] No such file or directory: '/home/runner/.local/share/undetected_chromedriver/undetected/chromedriver-linux64/chromedriver' -> '/home/runner/.local/share/undetected_chromedriver/undetected_chromedriver'

During handling of the above exception, another exception occurred:

Traceback (most recent call last):
  File "/home/runner/workspace/bot/stealth_bot.py", line 258, in _create_driver
    driver = Chrome(options=options)
             ^^^^^^^^^^^^^^^^^^^^^^^
  File "/home/runner/workspace/.pythonlibs/lib/python3.11/site-packages/selenium/webdriver/chrome/webdriver.py", line 47, in __init__
    super().__init__(
  File "/home/runner/workspace/.pythonlibs/lib/python3.11/site-packages/selenium/webdriver/chromium/webdriver.py", line 58, in __init__
    self.service.start()
  File "/home/runner/workspace/.pythonlibs/lib/python3.11/site-packages/selenium/webdriver/common/service.py", line 106, in start
    self.assert_process_still_running()
  File "/home/runner/workspace/.pythonlibs/lib/python3.11/site-packages/selenium/webdriver/common/service.py", line 119, in assert_process_still_running
    raise WebDriverException(f"Service {self._path} unexpectedly exited. Status code was: {return_code}")
selenium.common.exceptions.WebDriverException: Message: Service /home/runner/.cache/selenium/chromedriver/linux64/125.0.6422.141/chromedriver unexpectedly exited. Status code was: 127


During handling of the above exception, another exception occurred:

Traceback (most recent call last):
  File "/home/runner/workspace/bot/stealth_bot.py", line 282, in _create_driver
    driver = Chrome(options=basic_options)
             ^^^^^^^^^^^^^^^^^^^^^^^^^^^^^
  File "/home/runner/workspace/.pythonlibs/lib/python3.11/site-packages/selenium/webdriver/chrome/webdriver.py", line 47, in __init__
    super().__init__(
  File "/home/runner/workspace/.pythonlibs/lib/python3.11/site-packages/selenium/webdriver/chromium/webdriver.py", line 58, in __init__
    self.service.start()
  File "/home/runner/workspace/.pythonlibs/lib/python3.11/site-packages/selenium/webdriver/common/service.py", line 106, in start
    self.assert_process_still_running()
  File "/home/runner/workspace/.pythonlibs/lib/python3.11/site-packages/selenium/webdriver/common/service.py", line 119, in assert_process_still_running
    raise WebDriverException(f"Service {self._path} unexpectedly exited. Status code was: {return_code}")
selenium.common.exceptions.WebDriverException: Message: Service /home/runner/.cache/selenium/chromedriver/linux64/125.0.6422.141/chromedriver unexpectedly exited. Status code was: 127


During handling of the above exception, another exception occurred:

Traceback (most recent call last):
  File "/home/runner/workspace/bot/stealth_bot.py", line 519, in run
    self.driver = self._create_driver()
                  ^^^^^^^^^^^^^^^^^^^^^
  File "/home/runner/workspace/bot/stealth_bot.py", line 287, in _create_driver
    raise Exception(f"Cannot create Chrome driver. Original error: {e}, Final error: {final_error}")
Exception: Cannot create Chrome driver. Original error: Message: Service /home/runner/.cache/selenium/chromedriver/linux64/125.0.6422.141/chromedriver unexpectedly exited. Status code was: 127
, Final error: Message: Service /home/runner/.cache/selenium/chromedriver/linux64/125.0.6422.141/chromedriver unexpectedly exited. Status code was: 127

2025-06-05 05:46:40 | ERROR    | stealth_bot:539 | Fatal error during bot execution: Cannot create Chrome driver. Original error: Message: Service /home/runner/.cache/selenium/chromedriver/linux64/125.0.6422.141/chromedriver unexpectedly exited. Status code was: 127
, Final error: Message: Service /home/runner/.cache/selenium/chromedriver/linux64/125.0.6422.141/chromedriver unexpectedly exited. Status code was: 127
Traceback (most recent call last):
  File "/home/runner/workspace/bot/stealth_bot.py", line 242, in _create_driver
    driver = uc.Chrome(
             ^^^^^^^^^^
  File "/home/runner/workspace/.pythonlibs/lib/python3.11/site-packages/undetected_chromedriver/__init__.py", line 466, in __init__
    super(Chrome, self).__init__(
  File "/home/runner/workspace/.pythonlibs/lib/python3.11/site-packages/selenium/webdriver/chrome/webdriver.py", line 47, in __init__
    super().__init__(
  File "/home/runner/workspace/.pythonlibs/lib/python3.11/site-packages/selenium/webdriver/chromium/webdriver.py", line 58, in __init__
    self.service.start()
  File "/home/runner/workspace/.pythonlibs/lib/python3.11/site-packages/selenium/webdriver/common/service.py", line 106, in start
    self.assert_process_still_running()
  File "/home/runner/workspace/.pythonlibs/lib/python3.11/site-packages/selenium/webdriver/common/service.py", line 119, in assert_process_still_running
    raise WebDriverException(f"Service {self._path} unexpectedly exited. Status code was: {return_code}")
selenium.common.exceptions.WebDriverException: Message: Service /home/runner/.local/share/undetected_chromedriver/undetected_chromedriver unexpectedly exited. Status code was: 127


During handling of the above exception, another exception occurred:

Traceback (most recent call last):
  File "/home/runner/workspace/bot/stealth_bot.py", line 258, in _create_driver
    driver = Chrome(options=options)
             ^^^^^^^^^^^^^^^^^^^^^^^
  File "/home/runner/workspace/.pythonlibs/lib/python3.11/site-packages/selenium/webdriver/chrome/webdriver.py", line 47, in __init__
    super().__init__(
  File "/home/runner/workspace/.pythonlibs/lib/python3.11/site-packages/selenium/webdriver/chromium/webdriver.py", line 58, in __init__
    self.service.start()
  File "/home/runner/workspace/.pythonlibs/lib/python3.11/site-packages/selenium/webdriver/common/service.py", line 106, in start
    self.assert_process_still_running()
  File "/home/runner/workspace/.pythonlibs/lib/python3.11/site-packages/selenium/webdriver/common/service.py", line 119, in assert_process_still_running
    raise WebDriverException(f"Service {self._path} unexpectedly exited. Status code was: {return_code}")
selenium.common.exceptions.WebDriverException: Message: Service /home/runner/.cache/selenium/chromedriver/linux64/125.0.6422.141/chromedriver unexpectedly exited. Status code was: 127


During handling of the above exception, another exception occurred:

Traceback (most recent call last):
  File "/home/runner/workspace/bot/stealth_bot.py", line 282, in _create_driver
    driver = Chrome(options=basic_options)
             ^^^^^^^^^^^^^^^^^^^^^^^^^^^^^
  File "/home/runner/workspace/.pythonlibs/lib/python3.11/site-packages/selenium/webdriver/chrome/webdriver.py", line 47, in __init__
    super().__init__(
  File "/home/runner/workspace/.pythonlibs/lib/python3.11/site-packages/selenium/webdriver/chromium/webdriver.py", line 58, in __init__
    self.service.start()
  File "/home/runner/workspace/.pythonlibs/lib/python3.11/site-packages/selenium/webdriver/common/service.py", line 106, in start
    self.assert_process_still_running()
  File "/home/runner/workspace/.pythonlibs/lib/python3.11/site-packages/selenium/webdriver/common/service.py", line 119, in assert_process_still_running
    raise WebDriverException(f"Service {self._path} unexpectedly exited. Status code was: {return_code}")
selenium.common.exceptions.WebDriverException: Message: Service /home/runner/.cache/selenium/chromedriver/linux64/125.0.6422.141/chromedriver unexpectedly exited. Status code was: 127


During handling of the above exception, another exception occurred:

Traceback (most recent call last):
  File "/home/runner/workspace/bot/stealth_bot.py", line 519, in run
    self.driver = self._create_driver()
                  ^^^^^^^^^^^^^^^^^^^^^
  File "/home/runner/workspace/bot/stealth_bot.py", line 287, in _create_driver
    raise Exception(f"Cannot create Chrome driver. Original error: {e}, Final error: {final_error}")
Exception: Cannot create Chrome driver. Original error: Message: Service /home/runner/.cache/selenium/chromedriver/linux64/125.0.6422.141/chromedriver unexpectedly exited. Status code was: 127
, Final error: Message: Service /home/runner/.cache/selenium/chromedriver/linux64/125.0.6422.141/chromedriver unexpectedly exited. Status code was: 127

2025-06-05 05:53:01 | ERROR    | stealth_bot:271 | Failed to create Chrome driver: Message: Service /home/runner/.cache/selenium/chromedriver/linux64/125.0.6422.141/chromedriver unexpectedly exited. Status code was: 127

2025-06-05 05:53:01 | ERROR    | stealth_bot:286 | All driver creation attempts failed: Message: Service /home/runner/.cache/selenium/chromedriver/linux64/125.0.6422.141/chromedriver unexpectedly exited. Status code was: 127

2025-06-05 05:53:01 | ERROR    | stealth_bot:539 | Fatal error during bot execution: Cannot create Chrome driver. Original error: Message: Service /home/runner/.cache/selenium/chromedriver/linux64/125.0.6422.141/chromedriver unexpectedly exited. Status code was: 127
, Final error: Message: Service /home/runner/.cache/selenium/chromedriver/linux64/125.0.6422.141/chromedriver unexpectedly exited. Status code was: 127
Traceback (most recent call last):
  File "/home/runner/workspace/bot/stealth_bot.py", line 242, in _create_driver
    driver = uc.Chrome(
             ^^^^^^^^^^
  File "/home/runner/workspace/.pythonlibs/lib/python3.11/site-packages/undetected_chromedriver/__init__.py", line 466, in __init__
    super(Chrome, self).__init__(
  File "/home/runner/workspace/.pythonlibs/lib/python3.11/site-packages/selenium/webdriver/chrome/webdriver.py", line 47, in __init__
    super().__init__(
  File "/home/runner/workspace/.pythonlibs/lib/python3.11/site-packages/selenium/webdriver/chromium/webdriver.py", line 58, in __init__
    self.service.start()
  File "/home/runner/workspace/.pythonlibs/lib/python3.11/site-packages/selenium/webdriver/common/service.py", line 106, in start
    self.assert_process_still_running()
  File "/home/runner/workspace/.pythonlibs/lib/python3.11/site-packages/selenium/webdriver/common/service.py", line 119, in assert_process_still_running
    raise WebDriverException(f"Service {self._path} unexpectedly exited. Status code was: {return_code}")
selenium.common.exceptions.WebDriverException: Message: Service /home/runner/.local/share/undetected_chromedriver/undetected_chromedriver unexpectedly exited. Status code was: 127


During handling of the above exception, another exception occurred:

Traceback (most recent call last):
  File "/home/runner/workspace/bot/stealth_bot.py", line 258, in _create_driver
    driver = Chrome(options=options)
             ^^^^^^^^^^^^^^^^^^^^^^^
  File "/home/runner/workspace/.pythonlibs/lib/python3.11/site-packages/selenium/webdriver/chrome/webdriver.py", line 47, in __init__
    super().__init__(
  File "/home/runner/workspace/.pythonlibs/lib/python3.11/site-packages/selenium/webdriver/chromium/webdriver.py", line 58, in __init__
    self.service.start()
  File "/home/runner/workspace/.pythonlibs/lib/python3.11/site-packages/selenium/webdriver/common/service.py", line 106, in start
    self.assert_process_still_running()
  File "/home/runner/workspace/.pythonlibs/lib/python3.11/site-packages/selenium/webdriver/common/service.py", line 119, in assert_process_still_running
    raise WebDriverException(f"Service {self._path} unexpectedly exited. Status code was: {return_code}")
selenium.common.exceptions.WebDriverException: Message: Service /home/runner/.cache/selenium/chromedriver/linux64/125.0.6422.141/chromedriver unexpectedly exited. Status code was: 127


During handling of the above exception, another exception occurred:

Traceback (most recent call last):
  File "/home/runner/workspace/bot/stealth_bot.py", line 282, in _create_driver
    driver = Chrome(options=basic_options)
             ^^^^^^^^^^^^^^^^^^^^^^^^^^^^^
  File "/home/runner/workspace/.pythonlibs/lib/python3.11/site-packages/selenium/webdriver/chrome/webdriver.py", line 47, in __init__
    super().__init__(
  File "/home/runner/workspace/.pythonlibs/lib/python3.11/site-packages/selenium/webdriver/chromium/webdriver.py", line 58, in __init__
    self.service.start()
  File "/home/runner/workspace/.pythonlibs/lib/python3.11/site-packages/selenium/webdriver/common/service.py", line 106, in start
    self.assert_process_still_running()
  File "/home/runner/workspace/.pythonlibs/lib/python3.11/site-packages/selenium/webdriver/common/service.py", line 119, in assert_process_still_running
    raise WebDriverException(f"Service {self._path} unexpectedly exited. Status code was: {return_code}")
selenium.common.exceptions.WebDriverException: Message: Service /home/runner/.cache/selenium/chromedriver/linux64/125.0.6422.141/chromedriver unexpectedly exited. Status code was: 127


During handling of the above exception, another exception occurred:

Traceback (most recent call last):
  File "/home/runner/workspace/bot/stealth_bot.py", line 519, in run
    self.driver = self._create_driver()
                  ^^^^^^^^^^^^^^^^^^^^^
  File "/home/runner/workspace/bot/stealth_bot.py", line 287, in _create_driver
    raise Exception(f"Cannot create Chrome driver. Original error: {e}, Final error: {final_error}")
Exception: Cannot create Chrome driver. Original error: Message: Service /home/runner/.cache/selenium/chromedriver/linux64/125.0.6422.141/chromedriver unexpectedly exited. Status code was: 127
, Final error: Message: Service /home/runner/.cache/selenium/chromedriver/linux64/125.0.6422.141/chromedriver unexpectedly exited. Status code was: 127

2025-06-05 05:53:01 | ERROR    | stealth_bot:271 | Failed to create Chrome driver: Message: Service /home/runner/.cache/selenium/chromedriver/linux64/125.0.6422.141/chromedriver unexpectedly exited. Status code was: 127

2025-06-05 05:53:01 | ERROR    | stealth_bot:286 | All driver creation attempts failed: Message: Service /home/runner/.cache/selenium/chromedriver/linux64/125.0.6422.141/chromedriver unexpectedly exited. Status code was: 127

2025-06-05 05:53:01 | ERROR    | stealth_bot:539 | Fatal error during bot execution: Cannot create Chrome driver. Original error: Message: Service /home/runner/.cache/selenium/chromedriver/linux64/125.0.6422.141/chromedriver unexpectedly exited. Status code was: 127
, Final error: Message: Service /home/runner/.cache/selenium/chromedriver/linux64/125.0.6422.141/chromedriver unexpectedly exited. Status code was: 127
Traceback (most recent call last):
  File "/home/runner/workspace/bot/stealth_bot.py", line 242, in _create_driver
    driver = uc.Chrome(
             ^^^^^^^^^^
  File "/home/runner/workspace/.pythonlibs/lib/python3.11/site-packages/undetected_chromedriver/__init__.py", line 466, in __init__
    super(Chrome, self).__init__(
  File "/home/runner/workspace/.pythonlibs/lib/python3.11/site-packages/selenium/webdriver/chrome/webdriver.py", line 47, in __init__
    super().__init__(
  File "/home/runner/workspace/.pythonlibs/lib/python3.11/site-packages/selenium/webdriver/chromium/webdriver.py", line 58, in __init__
    self.service.start()
  File "/home/runner/workspace/.pythonlibs/lib/python3.11/site-packages/selenium/webdriver/common/service.py", line 106, in start
    self.assert_process_still_running()
  File "/home/runner/workspace/.pythonlibs/lib/python3.11/site-packages/selenium/webdriver/common/service.py", line 119, in assert_process_still_running
    raise WebDriverException(f"Service {self._path} unexpectedly exited. Status code was: {return_code}")
selenium.common.exceptions.WebDriverException: Message: Service /home/runner/.local/share/undetected_chromedriver/undetected_chromedriver unexpectedly exited. Status code was: 127


During handling of the above exception, another exception occurred:

Traceback (most recent call last):
  File "/home/runner/workspace/bot/stealth_bot.py", line 258, in _create_driver
    driver = Chrome(options=options)
             ^^^^^^^^^^^^^^^^^^^^^^^
  File "/home/runner/workspace/.pythonlibs/lib/python3.11/site-packages/selenium/webdriver/chrome/webdriver.py", line 47, in __init__
    super().__init__(
  File "/home/runner/workspace/.pythonlibs/lib/python3.11/site-packages/selenium/webdriver/chromium/webdriver.py", line 58, in __init__
    self.service.start()
  File "/home/runner/workspace/.pythonlibs/lib/python3.11/site-packages/selenium/webdriver/common/service.py", line 106, in start
    self.assert_process_still_running()
  File "/home/runner/workspace/.pythonlibs/lib/python3.11/site-packages/selenium/webdriver/common/service.py", line 119, in assert_process_still_running
    raise WebDriverException(f"Service {self._path} unexpectedly exited. Status code was: {return_code}")
selenium.common.exceptions.WebDriverException: Message: Service /home/runner/.cache/selenium/chromedriver/linux64/125.0.6422.141/chromedriver unexpectedly exited. Status code was: 127


During handling of the above exception, another exception occurred:

Traceback (most recent call last):
  File "/home/runner/workspace/bot/stealth_bot.py", line 282, in _create_driver
    driver = Chrome(options=basic_options)
             ^^^^^^^^^^^^^^^^^^^^^^^^^^^^^
  File "/home/runner/workspace/.pythonlibs/lib/python3.11/site-packages/selenium/webdriver/chrome/webdriver.py", line 47, in __init__
    super().__init__(
  File "/home/runner/workspace/.pythonlibs/lib/python3.11/site-packages/selenium/webdriver/chromium/webdriver.py", line 58, in __init__
    self.service.start()
  File "/home/runner/workspace/.pythonlibs/lib/python3.11/site-packages/selenium/webdriver/common/service.py", line 106, in start
    self.assert_process_still_running()
  File "/home/runner/workspace/.pythonlibs/lib/python3.11/site-packages/selenium/webdriver/common/service.py", line 119, in assert_process_still_running
    raise WebDriverException(f"Service {self._path} unexpectedly exited. Status code was: {return_code}")
selenium.common.exceptions.WebDriverException: Message: Service /home/runner/.cache/selenium/chromedriver/linux64/125.0.6422.141/chromedriver unexpectedly exited. Status code was: 127


During handling of the above exception, another exception occurred:

Traceback (most recent call last):
  File "/home/runner/workspace/bot/stealth_bot.py", line 519, in run
    self.driver = self._create_driver()
                  ^^^^^^^^^^^^^^^^^^^^^
  File "/home/runner/workspace/bot/stealth_bot.py", line 287, in _create_driver
    raise Exception(f"Cannot create Chrome driver. Original error: {e}, Final error: {final_error}")
Exception: Cannot create Chrome driver. Original error: Message: Service /home/runner/.cache/selenium/chromedriver/linux64/125.0.6422.141/chromedriver unexpectedly exited. Status code was: 127
, Final error: Message: Service /home/runner/.cache/selenium/chromedriver/linux64/125.0.6422.141/chromedriver unexpectedly exited. Status code was: 127

